# 错误处理
[TOC]

错误处理（error handling）是处理可能发生失败情况的过程。例如读取一个文件失败，然后继续使用这个失效的输入显然是有问题的。错误处理允许我们以一种显式的方式来发现并处理这类错误，避免了其余代码发生潜在的问题。

有关错误处理的更多内容，可参考[官方文档](https://doc.rust-lang.org/book/ch09-00-error-handling.html)的错误处理的章节。

Rust 有一套独特的处理异常情况的机制，它并不像其它语言中的 try 机制那样简单。

首先，程序中一般会出现两种错误：可恢复错误和不可恢复错误。

可恢复错误的典型案例是文件访问错误，如果访问一个文件失败，有可能是因为它正在被占用，是正常的，我们可以通过等待来解决。

但还有一种错误是由编程中无法解决的逻辑错误导致的，例如访问数组末尾以外的位置。

大多数编程语言不区分这两种错误，并用 Exception （异常）类来表示错误。在 Rust 中没有 Exception。

对于可恢复错误用 `Result<T, E>` 类来处理，对于不可恢复错误使用 `panic!` 宏来处理。

## 不可恢复错误

在本章之前我们讲过宏，里面就提到`panic!`，这个就是不可恢复的错误❎。是啊，都崩溃了，还恢复个毛线啊。
```rust
fn main() {
    panic!("错误❎崩溃。");
    println!("Hello, Rust");
}
```

运行一下：

```shell
 cargo run -q
warning: unreachable statement
 --> src/main.rs:3:5
  |
2 |     panic!("错误❎崩溃。");
  |     ----------------------- any code following this expression is unreachable
3 |     println!("Hello, Rust");
  |     ^^^^^^^^^^^^^^^^^^^^^^^^ unreachable statement
  |
  = note: `#[warn(unreachable_code)]` on by default
  = note: this warning originates in a macro (in Nightly builds, run with -Z macro-backtrace for more info)

warning: 1 warning emitted

thread 'main' panicked at '错误❎崩溃。', src/main.rs:2:5
note: run with `RUST_BACKTRACE=1` environment variable to display a backtrace
```

编译提示程序永远不会运行到`println!("Hello, Rust");`

这里面还有一句英文：run with `RUST_BACKTRACE=1` environment variable to display a backtrace，翻译过来的意思是："通过 `RUST_BACKTRACE=1` 环境变量运行以显示回溯"。接下来我们将介绍回溯（backtrace）。

如果你使用的是 Linux 或 macOS 等 UNIX 系统：
```shell
RUST_BACKTRACE=1 cargo run
```

如果你使用的是 Windows系统：

```shell
$env:RUST_BACKTRACE=1 ; cargo run
```

运行完了会看到下面的信息：

```shell
stack backtrace:
   0: std::panicking::begin_panic
             at /Users/greendoralvdora/.rustup/toolchains/stable-x86_64-apple-darwin/lib/rustlib/src/rust/library/std/src/panicking.rs:519:12
   1: sunny_error01::main
             at ./src/main.rs:2:5
   2: core::ops::function::FnOnce::call_once
             at /Users/greendoralvdora/.rustup/toolchains/stable-x86_64-apple-darwin/lib/rustlib/src/rust/library/core/src/ops/function.rs:227:5
note: Some details are omitted, run with `RUST_BACKTRACE=full` for a verbose backtrace.

```

回溯是不可恢复错误的另一种处理方式，它会展开运行的栈并输出所有的信息，然后程序依然会退出。我们可以找到我们编写的 panic! 宏触发的错误。

## 可恢复的错误

上一张，我们讲测试的时候，最后一部分就是讲如何使用`Result<T, E>`控制测试，这个可恢复的错误也是使用`Result<T, E>`，首先让我们再说一些在核心代码里面`Result<T, E>`是如何定义的：
```rust
enum Result<T, E> {
    Ok(T),
    Err(E),
}
```

在 Rust 标准库中可能产生异常的函数的返回值都是 Result 类型的。例如：当我们尝试打开一个文件时：
```rust
use std::error::Error;

fn main() {
    let _ri=read_issue();
}

fn read_issue() -> Result<String, Box<dyn Error>> {
    Ok(std::fs::read_to_string("/etc/issue")?)
}
```

>`?` 符的实际作用是将 `Result` 类非异常的值直接取出，如果有异常就将异常 `Result` 返回出去。所以，`?` 符仅用于返回值类型为 `Result<T, E> `的函数，其中 `E `类型必须和 `?` 所处理的 `Result 的 E `类型一致。

这个虽然加上了异常处理，但是如果文件没有，也是直接`panic!`,下面我们做以下调整：
```rust
use std::error::Error;

fn main() {
    let ri=read_issue();
    match ri {
        Ok(issue) => {
            println!("{}",issue);
        },
        Err(_err) => {
            println!("Failed to open the file.");
        }
    }
}

fn read_issue() -> Result<String, Box<dyn Error>> {
    Ok(std::fs::read_to_string("/etc/issue")?)
}
```

这下在MacOS下显示的结果是：
```shell
$ cargo run -q
Failed to open the file.
```
在ubuntu下显示的结果是：
```shell
$ cargo run -q
Ubuntu 18.04.5 LTS \n \l
````

当然还有一种简写的形式:
```rust
use std::error::Error;

fn main() {
    let ri = read_issue();
    if let Ok(issue) = ri {
        println!("{}", issue);
    } else {
        println!("Failed to open the file.");
    }
}

fn read_issue() -> Result<String, Box<dyn Error>> {
    Ok(std::fs::read_to_string("/etc/issue")?)
}
```

如果想使一个可恢复错误按不可恢复错误处理，Result 类提供了两个办法：unwrap() 和 expect(message: &str) ：
```rust
let ri1 = read_issue().unwrap();
let ri2 = read_issue().expect("Failed to open.");
```
这段程序相当于在 `Result` 为 `Err` 时调用 `panic! 宏`。两者的区别在于 `expect` 能够向` panic!` 宏发送一段指定的错误信息。

## kind 方法
到此为止，Rust 似乎没有像 `try` 块一样的语法，但这样并不意味着 Rust 实现不了：我们完全可以把 `try `块在独立的函数中实现，将所有的异常都传递出去解决。实际上这才是一个分化良好的程序应当遵循的编程方法：应该注重独立功能的完整性。

但是这样需要判断 `Result` 的 `Err` 类型，获取 `Err` 类型的函数是 `kind()`:

```rust
use std::io;
fn main() {
    let ri = read_issue();
    match ri {
        Ok(issue) => {
            println!("{}", issue);
        }
        Err(e) => match e.kind() {
            io::ErrorKind::NotFound => {
                println!("No such file");
            }
            _ => {
                println!("Cannot read the file");
            }
        },
    }
}

fn read_issue() -> Result<String, io::Error> {
    Ok(std::fs::read_to_string("/etc/issue")?)
}
```

这个是把`use std::error::Error;`换成了`use std::io;`,这就可以精准的知道是什么错误了。